### **Exception Propagation**
When a method throws an exception, if the current method does not catch it, the exception is thrown up to the calling method, until it is caught by a `try ... catch`:

```java
// exception
public class Main {
    public static void main(String[] args) {
        try {
            process1();
        } catch (Exception e) {
            e.printStackTrace();
        }
    }

    static void process1() {
        process2();
    }

    static void process2() {
        Integer.parseInt(null); // Will throw NumberFormatException
    }
}
```

`printStackTrace()` prints the call stack, which is very useful for debugging errors. The exception indicates that `NumberFormatException` was thrown in the `Integer.parseInt` method. The call hierarchy from bottom to top is as follows:

- `main()` calls `process1()`.
- `process1()` calls `process2()`.
- `process2()` calls `Integer.parseInt(String)`.
- `Integer.parseInt(String)` calls `Integer.parseInt(String, int)`.

**Throwing Exceptions**
When an error occurs, such as when a user inputs invalid characters, we can throw an exception.

To throw an exception, follow two steps:

1. Create an instance of some `Exception`.
2. Use the `throw` statement to throw it.

Here's an example:

```java
void process2(String s) {
    if (s == null) {
        NullPointerException e = new NullPointerException();
        throw e;
    }
}
```

Mostly, the code to throw an exception is combined into one line:

```java
void process2(String s) {
    if (s == null) {
        throw new NullPointerException();
    }
}
```

If a method catches an exception and then throws a new one, it effectively "converts" the type of thrown exception:

```java
void process1(String s) {
    try {
        process2();
    } catch (NullPointerException e) {
        throw new IllegalArgumentException();
    }
}

void process2(String s) {
    if (s == null) {
        throw new NullPointerException();
    }
}
```

When `process2()` throws a `NullPointerException`, it's caught by `process1()` and then `IllegalArgumentException` is thrown.

**Exception Masking**
If an exception is thrown in the `finally` block, the exception from the `catch` block gets suppressed. For instance, if `finally` throws an `IllegalArgumentException`, the original exception prepared to be thrown in the `catch` block disappears because only one exception can be thrown at a time.

In rare cases, we might need to know all exceptions. To preserve all exception information, first save the original exception in an `origin` variable, then use `Throwable.addSuppressed()` to add the original exception, and finally throw the new exception in `finally`:

```java
// exception
public class Main {
    public static void main(String[] args) throws Exception {
        Exception origin = null;
        try {
            System.out.println(Integer.parseInt("abc"));
        } catch (Exception e) {
            origin = e;
            throw e;
        } finally {
            Exception e = new IllegalArgumentException();
            if (origin != null) {
                e.addSuppressed(origin);
            }
            throw e;
        }
    }
}
```

When both `catch` and `finally` throw exceptions, although the exception from `catch` is suppressed, the exception thrown from `finally` still contains it:

```
Exception in thread "main" java.lang.IllegalArgumentException
    at Main.main(Main.java:11)
Suppressed: java.lang.NumberFormatException: For input string: "abc"
    at java.base/java.lang.NumberFormatException.forInputString(NumberFormatException.java:65)
    at java.base/java.lang.Integer.parseInt(Integer.java:652)
    at java.base/java.lang.Integer.parseInt(Integer.java:770)
    at Main.main(Main.java:6)
```
